Traceback (most recent call last):
  File "/Users/jrladd/Library/Python/3.9/lib/python/site-packages/jupyter_cache/executors/utils.py", line 58, in single_nb_execution
    executenb(
  File "/Users/jrladd/Library/Python/3.9/lib/python/site-packages/nbclient/client.py", line 1204, in execute
    return NotebookClient(nb=nb, resources=resources, km=km, **kwargs).execute()
  File "/Users/jrladd/Library/Python/3.9/lib/python/site-packages/nbclient/util.py", line 84, in wrapped
    return just_run(coro(*args, **kwargs))
  File "/Users/jrladd/Library/Python/3.9/lib/python/site-packages/nbclient/util.py", line 62, in just_run
    return loop.run_until_complete(coro)
  File "/Library/Developer/CommandLineTools/Library/Frameworks/Python3.framework/Versions/3.9/lib/python3.9/asyncio/base_events.py", line 642, in run_until_complete
    return future.result()
  File "/Users/jrladd/Library/Python/3.9/lib/python/site-packages/nbclient/client.py", line 663, in async_execute
    await self.async_execute_cell(
  File "/Users/jrladd/Library/Python/3.9/lib/python/site-packages/nbclient/client.py", line 965, in async_execute_cell
    await self._check_raise_for_error(cell, cell_index, exec_reply)
  File "/Users/jrladd/Library/Python/3.9/lib/python/site-packages/nbclient/client.py", line 862, in _check_raise_for_error
    raise CellExecutionError.from_cell_and_msg(cell, exec_reply_content)
nbclient.exceptions.CellExecutionError: An error occurred while executing the following cell:
------------------
len(marvel.nodes) # Number of nodes
------------------

[0;31m---------------------------------------------------------------------------[0m
[0;31mAttributeError[0m                            Traceback (most recent call last)
Cell [0;32mIn[18], line 1[0m
[0;32m----> 1[0m [38;5;28mlen[39m([43mmarvel[49m[38;5;241;43m.[39;49m[43mnodes[49m) [38;5;66;03m# Number of nodes[39;00m

File [0;32m~/Library/Python/3.9/lib/python/site-packages/pandas/core/generic.py:5902[0m, in [0;36mNDFrame.__getattr__[0;34m(self, name)[0m
[1;32m   5895[0m [38;5;28;01mif[39;00m (
[1;32m   5896[0m     name [38;5;129;01mnot[39;00m [38;5;129;01min[39;00m [38;5;28mself[39m[38;5;241m.[39m_internal_names_set
[1;32m   5897[0m     [38;5;129;01mand[39;00m name [38;5;129;01mnot[39;00m [38;5;129;01min[39;00m [38;5;28mself[39m[38;5;241m.[39m_metadata
[1;32m   5898[0m     [38;5;129;01mand[39;00m name [38;5;129;01mnot[39;00m [38;5;129;01min[39;00m [38;5;28mself[39m[38;5;241m.[39m_accessors
[1;32m   5899[0m     [38;5;129;01mand[39;00m [38;5;28mself[39m[38;5;241m.[39m_info_axis[38;5;241m.[39m_can_hold_identifiers_and_holds_name(name)
[1;32m   5900[0m ):
[1;32m   5901[0m     [38;5;28;01mreturn[39;00m [38;5;28mself[39m[name]
[0;32m-> 5902[0m [38;5;28;01mreturn[39;00m [38;5;28;43mobject[39;49m[38;5;241;43m.[39;49m[38;5;21;43m__getattribute__[39;49m[43m([49m[38;5;28;43mself[39;49m[43m,[49m[43m [49m[43mname[49m[43m)[49m

[0;31mAttributeError[0m: 'DataFrame' object has no attribute 'nodes'
AttributeError: 'DataFrame' object has no attribute 'nodes'

